<?xml version="1.0" encoding="utf-8"?>
<!-- This URDF was automatically created by SolidWorks to URDF Exporter! Originally created by Stephen Brawner (brawner@gmail.com) 
     Commit Version: 1.6.0-4-g7f85cfe  Build Version: 1.6.7995.38578
     For more information, please see http://wiki.ros.org/sw_urdf_exporter -->
<robot name="AGV">
  <!-- ****************** ROBOT BASE FOOTPRINT ***************************  -->
  <!-- Define the center of the main robot chassis projected on the ground -->
  <link name="base_footprint"/>
  <!-- The base footprint of the robot is located underneath the chassis -->
  <joint name="base_joint" type="fixed">
    <parent link="base_footprint"/>
    <child link="base_link" />
    <origin xyz="0.0 0.0 0.0" rpy="0 0 0"/>
  </joint>
  <!-- ********************** ROBOT BASE *********************************  -->
  <link
    name="base_link">
    <inertial>
      <origin
        xyz="-0.0347079733853149 -2.71434722480272E-18 0.146406568567285"
        rpy="0 0 0" />
      <mass
        value="117.862714640598" />
      <inertia
        ixx="3.67900735879845"
        ixy="-0.000145451174823323"
        ixz="0.595391525291995"
        iyy="7.51796539557882"
        iyz="0.000383058746676954"
        izz="9.40950005235554" />
    </inertial>
    <visual>
      <origin
        xyz="0 0 0"
        rpy="0 0 0" />
      <geometry>
        <mesh
          filename="src/robot_pkg/meshes/base_link.STL" />
      </geometry>
      <material
        name="">
        <color
          rgba="0.792156862745098 0.819607843137255 0.933333333333333 1" />
      </material>
    </visual>
    <collision>
      <origin
        xyz="0 0 0"
        rpy="0 0 0" />
      <geometry>
        <mesh
          filename="src/robot_pkg/meshes/base_link.STL" />
      </geometry>
    </collision>
  </link>
  <link
    name="Left_wheel">
    <inertial>
      <origin
        xyz="6.9389E-18 1.3878E-17 -0.0225"
        rpy="0 0 0" />
      <mass
        value="0.78108" />
      <inertia
        ixx="0.0012497"
        ixy="-8.1315E-20"
        ixz="1.3307E-35"
        iyy="0.0012497"
        iyz="-8.1006E-36"
        izz="0.0022358" />
    </inertial>
    <visual>
      <origin
        xyz="0 0 0"
        rpy="1.5707963267949 0 0" />
      <geometry>
        <mesh
          filename="src/robot_pkg/meshes/Left_wheel.STL" />
      </geometry>
      <material
        name="">
        <color
          rgba="0.79216 0.81961 0.93333 1" />
      </material>
    </visual>
    <collision>
      <origin
        xyz="0 0 0"
        rpy="1.5707963267949 0 0" />
      <geometry>
        <mesh
          filename="src/robot_pkg/meshes/Left_wheel.STL" />
      </geometry>
    </collision>
  </link>
  <joint
    name="Left_wheel_joint"
    type="continuous">
    <origin
      xyz="0 -0.22 0.055"
      rpy="1.5707963267949 0.370242398388272 -3.14159265358979" />
    <parent
      link="base_link" />
    <child
      link="Left_wheel" />
    <axis
      xyz="0 1 0" />
  </joint>
  <link
    name="FR_caster">
    <inertial>
      <origin
        xyz="-5.5511E-17 1.0408E-17 -0.05"
        rpy="0 0 0" />
      <mass
        value="0.5236" />
      <inertia
        ixx="0.0005236"
        ixy="0"
        ixz="0"
        iyy="0.0005236"
        iyz="0"
        izz="0.0005236" />
    </inertial>
    <visual>
      <origin
        xyz="0 0 0"
        rpy="0 0 0" />
      <geometry>
        <mesh
          filename="src/robot_pkg/meshes/FR_caster.STL" />
      </geometry>
      <material
        name="">
        <color
          rgba="0.79216 0.81961 0.93333 1" />
      </material>
    </visual>
    <collision>
      <origin
        xyz="0 0 0"
        rpy="0 0 0" />
      <geometry>
        <mesh
          filename="src/robot_pkg/meshes/FR_caster.STL" />
      </geometry>
    </collision>
  </link>
  <joint
    name="FR_joint"
    type="fixed">
    <origin
      xyz="-0.3 0.1475 0.0305"
      rpy="1.5708 0 0" />
    <parent
      link="base_link" />
    <child
      link="FR_caster" />
    <axis
      xyz="0 0 0" />
  </joint>
  <link
    name="FL_caster">
    <inertial>
      <origin
        xyz="-5.5511E-17 1.0408E-17 0.05"
        rpy="0 0 0" />
      <mass
        value="0.5236" />
      <inertia
        ixx="0.0005236"
        ixy="0"
        ixz="0"
        iyy="0.0005236"
        iyz="0"
        izz="0.0005236" />
    </inertial>
    <visual>
      <origin
        xyz="0 0 0"
        rpy="0 0 0" />
      <geometry>
        <mesh
          filename="src/robot_pkg/meshes/FL_caster.STL" />
      </geometry>
      <material
        name="">
        <color
          rgba="0.79216 0.81961 0.93333 1" />
      </material>
    </visual>
    <collision>
      <origin
        xyz="0 0 0"
        rpy="0 0 0" />
      <geometry>
        <mesh
          filename="src/robot_pkg/meshes/FL_caster.STL" />
      </geometry>
    </collision>
  </link>
  <joint
    name="FL_joint"
    type="fixed">
    <origin
      xyz="-0.3 -0.1475 0.0305"
      rpy="1.5708 0 0" />
    <parent
      link="base_link" />
    <child
      link="FL_caster" />
    <axis
      xyz="0 0 0" />
  </joint>
  <link
    name="RR_caster">
    <inertial>
      <origin
        xyz="0.039172 -0.031856 -0.065338"
        rpy="0 0 0" />
      <mass
        value="0.5236" />
      <inertia
        ixx="0.0005236"
        ixy="5.421E-20"
        ixz="0"
        iyy="0.0005236"
        iyz="-1.3553E-20"
        izz="0.0005236" />
    </inertial>
    <visual>
      <origin
        xyz="0 0 0"
        rpy="0 0 0" />
      <geometry>
        <mesh
          filename="src/robot_pkg/meshes/RR_caster.STL" />
      </geometry>
      <material
        name="">
        <color
          rgba="0.79216 0.81961 0.93333 1" />
      </material>
    </visual>
    <collision>
      <origin
        xyz="0 0 0"
        rpy="0 0 0" />
      <geometry>
        <mesh
          filename="src/robot_pkg/meshes/RR_caster.STL" />
      </geometry>
    </collision>
  </link>
  <joint
    name="RR_joint"
    type="fixed">
    <origin
      xyz="0.3 0.11493 0.0305"
      rpy="1.5708 0 0" />
    <parent
      link="base_link" />
    <child
      link="RR_caster" />
    <axis
      xyz="0 0 0" />
  </joint>
  <link
    name="RL_wheel">
    <inertial>
      <origin
        xyz="0 1.0408E-17 0.05"
        rpy="0 0 0" />
      <mass
        value="0.5236" />
      <inertia
        ixx="0.0005236"
        ixy="0"
        ixz="0"
        iyy="0.0005236"
        iyz="0"
        izz="0.0005236" />
    </inertial>
    <visual>
      <origin
        xyz="0 0 0"
        rpy="0 0 0" />
      <geometry>
        <mesh
          filename="src/robot_pkg/meshes/RL_wheel.STL" />
      </geometry>
      <material
        name="">
        <color
          rgba="0.79216 0.81961 0.93333 1" />
      </material>
    </visual>
    <collision>
      <origin
        xyz="0 0 0"
        rpy="0 0 0" />
      <geometry>
        <mesh
          filename="src/robot_pkg/meshes/RL_wheel.STL" />
      </geometry>
    </collision>
  </link>
  <joint
    name="RL_joint"
    type="fixed">
    <origin
      xyz="0.3 -0.1475 0.0305"
      rpy="1.5708 0 0" />
    <parent
      link="base_link" />
    <child
      link="RL_wheel" />
    <axis
      xyz="0 0 0" />
  </joint>
  <link
    name="Right_wheel">
    <inertial>
      <origin
        xyz="-1.0192E-17 -2.0817E-17 -0.0225"
        rpy="0 0 0" />
      <mass
        value="0.78108" />
      <inertia
        ixx="0.0012497"
        ixy="1.6941E-21"
        ixz="-2.292E-35"
        iyy="0.0012497"
        iyz="3.2973E-36"
        izz="0.0022358" />
    </inertial>
    <visual>
      <origin
        xyz="0 0 0"
        rpy="0 0 0" />
      <geometry>
        <mesh
          filename="src/robot_pkg/meshes/Right_wheel.STL" />
      </geometry>
      <material
        name="">
        <color
          rgba="0.79216 0.81961 0.93333 1" />
      </material>
    </visual>
    <collision>
      <origin
        xyz="0 0 0"
        rpy="0 0 0" />
      <geometry>
        <mesh
          filename="src/robot_pkg/meshes/Right_wheel.STL" />
      </geometry>
    </collision>
  </link>
  <joint
    name="Right_wheel_joint"
    type="continuous">
    <origin
      xyz="0 0.22 0.055"
      rpy="1.5708 -0.013353 0" />
    <parent
      link="base_link" />
    <child
      link="Right_wheel" />
    <axis
      xyz="0 1 0" />
  </joint>
</robot>